Workbook

Sheet READ ME 
A1: FamInsureCo Data Analysis
A22: Now it's time for us to get started on our Data Analysis for FamInsureCo!
A23: As we've mentioned previously, there are a number of questions Management have expressed an interest in answering.
A25: • Do individuals who tend to have a higher Body Mass Index (BMI), have higher insurance costs? • Does region (geography) appear to have any impact on insurance costs? • Does the biological marker have any bearing with insurance costs? • Does the biological marker have any impact regarding insurance costs? (i.e. Do Men have higher insurance costs than women?) • Does smoking have any impact regarding insurance costs? • Do any correlations exist between medical charges and lifestyle?
A27: We'll seek to tackle this assignment in three parts.
A29: Firstly, you'll work on the Basic Desc. Statistics Tab where you'll make use of your knowledge of descriptive stats, to visualise the Medical Charges data. You'll be using the data in the FamInsureCo. Desc Stats Data Tab.
A30: Secondly, you'll work on the Intermediate Desc. Statistics Tab where you'll make use of your intermediate statistics knowledge, where you'll apply box and whisker plots and correlation analyses to identify the variables that have a linear relationship with medical charges. You'll be using the data in the FamInsureCo Int. Stats Data Tab.
A31: Thirdly, you'll then build out your presentation where you'll synthesize your insights for the FamInsureCo team!
A33: With this in mind, let's get started!
A35: Definitions
A36: We've included a high-level breakdown that explains the different columns you'll deal with in the FamInsureCo Desc. Stats Data Tab
A38: Age | B38: This column provides information on how old the individual is.
A39: Biological Marker | B39: This is a column filled with the individuals biological marker (i.e. Are they male or female).
A40: BMI | B40: This is a column that represents the Body Mass Index (BMI) of the respective individual. This is a commonly used metric to assess overhealth.
A41: Smoker | B41: This is a column that indicates whether the individual is a smoker or not.
A42: Region | B42: This is a column that indicates the geographical location of where the individual resides (i.e. Northwest, Northeast etc.)
A43: Medical_Insurance_Charges | B43: This is a column that represents the medical insurance charges incurred by that individual.

Sheet FamInsureCo Desc. Stats Data
A1: age | B1: biological marker | C1: bmi | D1: smoker | E1: region | F1: medical_insurance_charges
A2: 18 | B2: female | C2: 20.79 | D2: no | E2: southeast | F2: 1607.5101
A3: 18 | B3: female | C3: 24.09 | D3: no | E3: southeast | F3: 2201.0971
A4: 19 | B4: female | C4: 24.7 | D4: no | E4: southwest | F4: 1737.376
A5: 19 | B5: female | C5: 24.51 | D5: no | E5: northwest | F5: 2709.1119
A6: 19 | B6: female | C6: 22.515 | D6: no | E6: northwest | F6: 2117.3389
A7: 19 | B7: female | C7: 23.4 | D7: no | E7: southwest | F7: 2913.569
A8: 19 | B8: female | C8: 24.605 | D8: no | E8: northwest | F8: 2709.244
A9: 19 | B9: female | C9: 18.6 | D9: no | E9: southwest | F9: 1728.897
A10: 19 | B10: female | C10: 20.6 | D10: no | E10: southwest | F10: 1731.677
A11: 21 | B11: female | C11: 21.89 | D11: no | E11: southeast | F11: 3180.5101
A12: 21 | B12: female | C12: 22.135 | D12: no | E12: northeast | F12: 2585.8506
A13: 22 | B13: female | C13: 24.3 | D13: no | E13: southwest | F13: 2150.469
... A1339: 18 | B1339: male | C1339: 17.29 | D1339: yes | E1339: northeast | F1339: 12829.455

Sheet FamInsureCo Int. Stats Data
A1: age | B1: bmi | C1: BMI_Healthy | D1: BMI_Overweight | E1: BMI_Slightly_Overweight | F1: BMI_Underweight | G1: Biological Marker | H1: Smoker | I1: southeast | J1: southwest | K1: northwest | L1: northeast | M1: Young Adult | N1: Adult | O1: Mature Age Adult | P1: Senior | Q1: medical_insurance_charges
A2: 18 | B2: 20.79 | C2: 1 | D2: 0 | E2: 0 | F2: 0 | G2: 0 | H2: 0 | I2: 1 | J2: 0 | K2: 0 | L2: 0 | M2: 1 | N2: 0 | O2: 0 | P2: 0 | Q2: 1607.5101
A3: 18 | B3: 24.09 | C3: 1 | D3: 0 | E3: 0 | F3: 0 | G3: 0 | H3: 0 | I3: 1 | J3: 0 | K3: 0 | L3: 0 | M3: 1 | N3: 0 | O3: 0 | P3: 0 | Q3: 2201.0971
A4: 19 | B4: 24.7 | C4: 1 | D4: 0 | E4: 0 | F4: 0 | G4: 0 | H4: 0 | I4: 0 | J4: 1 | K4: 0 | L4: 0 | M4: 1 | N4: 0 | O4: 0 | P4: 0 | Q4: 1737.376
A5: 19 | B5: 24.51 | C5: 1 | D5: 0 | E5: 0 | F5: 0 | G5: 0 | H5: 0 | I5: 0 | J5: 0 | K5: 1 | L5: 0 | M5: 1 | N5: 0 | O5: 0 | P5: 0 | Q5: 2709.1119
A6: 19 | B6: 22.515 | C6: 1 | D6: 0 | E6: 0 | F6: 0 | G6: 0 | H6: 0 | I6: 0 | J6: 0 | K6: 1 | L6: 0 | M6: 1 | N6: 0 | O6: 0 | P6: 0 | Q6: 2117.3389
A7: 19 | B7: 23.4 | C7: 1 | D7: 0 | E7: 0 | F7: 0 | G7: 0 | H7: 0 | I7: 0 | J7: 1 | K7: 0 | L7: 0 | M7: 1 | N7: 0 | O7: 0 | P7: 0 | Q7: 2913.569
A8: 19 | B8: 24.605 | C8: 1 | D8: 0 | E8: 0 | F8: 0 | G8: 0 | H8: 0 | I8: 0 | J8: 0 | K8: 1 | L8: 0 | M8: 1 | N8: 0 | O8: 0 | P8: 0 | Q8: 2709.244
A9: 19 | B9: 18.6 | C9: 1 | D9: 0 | E9: 0 | F9: 0 | G9: 0 | H9: 0 | I9: 0 | J9: 1 | K9: 0 | L9: 0 | M9: 1 | N9: 0 | O9: 0 | P9: 0 | Q9: 1728.897
A10: 19 | B10: 20.6 | C10: 1 | D10: 0 | E10: 0 | F10: 0 | G10: 0 | H10: 0 | I10: 0 | J10: 1 | K10: 0 | L10: 0 | M10: 1 | N10: 0 | O10: 0 | P10: 0 | Q10: 1731.677
A11: 21 | B11: 21.89 | C11: 1 | D11: 0 | E11: 0 | F11: 0 | G11: 0 | H11: 0 | I11: 1 | J11: 0 | K11: 0 | L11: 0 | M11: 1 | N11: 0 | O11: 0 | P11: 0 | Q11: 3180.5101
A12: 21 | B12: 22.135 | C12: 1 | D12: 0 | E12: 0 | F12: 0 | G12: 0 | H12: 0 | I12: 0 | J12: 0 | K12: 0 | L12: 1 | M12: 1 | N12: 0 | O12: 0 | P12: 0 | Q12: 2585.8506
A13: 22 | B13: 24.3 | C13: 1 | D13: 0 | E13: 0 | F13: 0 | G13: 0 | H13: 0 | I13: 0 | J13: 1 | K13: 0 | L13: 0 | M13: 1 | N13: 0 | O13: 0 | P13: 0 | Q13: 2150.469
... A1339: 18 | B1339: 17.29 | C1339: 0 | D1339: 0 | E1339: 0 | F1339: 1 | G1339: 1 | H1339: 1 | I1339: 0 | J1339: 0 | K1339: 0 | L1339: 1 | M1339: 1 | N1339: 0 | O1339: 0 | P1339: 0 | Q1339: 12829.455

Sheet Answer_Check_Regression_Table
A1: SUMMARY OUTPUT
A3: Regression Statistics
A4: Multiple R | B4: 0.86882817
A5: R Square | B5: 0.75486239
A6: Adjusted R Square | B6: 0.75018959
A7: Standard Error | B7: 6025.1967
A8: Observations | B8: 1338
A10: ANOVA
B11: df | C11: SS | D11: MS | E11: F | F11: Significance F
A12: Regression | B12: 16 | C12: 1.4800906e+11 | D12: 9.250566e+09 | E12: 313.61908 | F12: 0
A13: Residual | B13: 1324 | C13: 4.8065166e+10 | D13: 36302995
A14: Total | B14: 1340 | C14: 1.9607422e+11
B16: Coefficients | C16: Standard Error | D16: t Stat | E16: P-value | F16: Lower 95% | G16: Upper 95%
A17: Intercept | B17: -5419.1366 | C17: 1997.8219 | D17: -2.7125223 | E17: 0.0067638255 | F17: -9338.3785 | G17: -1499.8947
A18: age | B18: 314.35099 | C18: 32.910137 | D18: 9.5517983 | E18: 5.9234823e-21 | F18: 249.78928 | G18: 378.91269
A19: bmi | B19: 150.93022 | C19: 53.724421 | D19: 2.8093409 | E19: 0.0050373057 | F19: 45.535938 | G19: 256.32449
A20: BMI_Healthy | B20: -2875.5181 | C20: 810.83119 | D20: -3.5463832 | E20: 0.00040418376 | F20: -4466.1721 | G20: -1284.864
A21: BMI_Overweight | B21: 0 | C21: 0 | D21: 65535 | E21: #NUM! | F21: 0 | G21: 0
A22: BMI_Slightly_Overweight | B22: -2592.2956 | C22: 555.59177 | D22: -4.6658279 | E22: #NUM! | F22: -3682.2318 | G22: -1502.3594
A23: BMI_Underweight | B23: -3294.8153 | C23: 1652.8407 | D23: -1.9934258 | E23: 0.046419739 | F23: -6537.2876 | G23: -52.342927
A24: Gender | B24: -113.82489 | C24: 330.91809 | D24: -0.34396695 | E24: 0.73092576 | F24: -763.00588 | G24: 535.35611
A25: Smoker | B25: 23881.962 | C25: 411.59304 | D25: 58.023241 | E25: 0 | F25: 23074.516 | G25: 24689.407
A26: southeast | B26: -546.82117 | C26: 478.67284 | D26: -1.1423693 | E26: 0.25350707 | F26: -1485.8611 | G26: 392.21878
A27: southwest | B27: -549.43006 | C27: 474.50852 | D27: -1.1578929 | E27: 0.24711656 | F27: -1480.3006 | G27: 381.44051
A28: northwest | B28: 0 | C28: 0 | D28: 65535 | E28: #NUM! | F28: 0 | G28: 0
A29: northeast | B29: 374.62163 | C29: 473.96149 | D29: 0.79040521 | E29: #NUM! | F29: -555.1758 | G29: 1304.4191
A30: Young Adult | B30: 0 | C30: 0 | D30: 65535 | E30: #NUM! | F30: 0 | G30: 0
A31: Adult | B31: -1563.6895 | C31: 596.53695 | D31: -2.6212786 | E31: #NUM! | F31: -2733.9503 | G31: -393.4288
A32: Mature Age Adult | B32: -2358.8165 | C32: 975.87568 | D32: -2.4171281 | E32: 0.015777935 | F32: -4273.2478 | G32: -444.38523
A33: Senior | B33: -2149.696 | C33: 1508.6485 | D33: -1.4249152 | E33: 0.1544174 | F33: -5109.2982 | G33: 809.90613

Sheet Intermediate Desc. Statistics
A1: Descriptive Statistics Analysis - Part II
A2: We've introduced you now to the concepts of intermediate statistics.
A3: Often in our data analysis, we need to move beyond simple statistics covering mean, mode, median and histograms and dive a bit deeper in our analysis.
A5: Using our previous Walmart example, say we've identified the average sales on the weekends versus weekdays and we've created a histogram showing the overall distribution of sales.
A6: What if we want to understand just how distributed the data is via the quartiles, or to view how much variability in sales exist for a specific day?
A7: Lastly, what about if we want to examine the relationship between sales and the discounts provided?
A9: Well, to answer those questions we'd seek to use quartiles, box plots and correlation analyses to better understand how we could answer these questions!
A10: With that in mind, let's get started!
A12: Previously we observed the overall distribution of medical insurance charges via a Histogram.
A13: While this helped us understand how medical charges were distributed - we don't have a hard metric regarding just how dispersed the medical insurance charges are.
A14: Wouldn't it be nice if we had a method to split our medical insurance into 4 neat quartiles, to help us better understand just how distributed our data is?
A15: That's exactly what we'll do in this question!
... A18: Note: We use the phrase quartile and percentile interchangeably. Use the Quantile() function to answer this question.
B19: Percentile | C19: 25 | D19: 50 | E19: 75 | F19: 100
C20: =_xlfn.QUARTILE.INC('FamInsureCo Desc. Stats Data'!$F$2:$F$1339,1) -> 4740.2872 | D20: =_xlfn.QUARTILE.INC('FamInsureCo Desc. Stats Data'!$F$2:$F$1339,2) -> 9382.033 | E20: =_xlfn.QUARTILE.INC('FamInsureCo Desc. Stats Data'!$F$2:$F$1339,3) -> 16639.913 | F20: =_xlfn.QUARTILE.INC('FamInsureCo Desc. Stats Data'!$F$2:$F$1339,4) -> 63770.428
B22: Interquantile Range | C22: =E20-C20 -> 11899.625
A25: Having now calculated the Interquartile Range, we have a better idea regarding how distributed the values are in our Medical Insurance Charges dataset.
A26: You might have recalled that we previously covered Box and Whisker Plots that enable us to see how the data is distributed based off quartiles.
A27: We've identified that smoking status, age and gender all seem to impact medical insurance charges to an extent.
A28: We haven't yet explored regions - so we'll look at this next with a box plot.
A29: Q8. Create a box plot using the Medical Insurance Charges and the Regions column, showing how costs are distributed across different living regions.
A30: Note: We've included an example of what your box and whisker plot should look like below!
A50: Observing our Box Plots, we don't see any particular changes with respect to Median Medical Charges.
A51: How about if we filter on Smoking Status? Do we see any substantial changes here?
A52: Q9. Create 2 Box Plots where Smoking Status = Yes and Smoking Status = No, using the Region and Medical Insurance Charges Columns. Does there appear to be a difference in costs regarding geography?
A53: Note: We've included an example for you so you'll know what to expect when you create your visualisation!
B54: Place your chart below here (Smoking = No ) | F54: Place your chart below here (Smoking = Yes )
A72: It seems that the prevalence of smoking seems to be quite a substantial factor when taking into lifestyle factors.
A73: Whilst we might be tempted to discount looking at gender, we haven't looked at the medical insurance charges of males/females who smoke. Let's investigate!
A74: Q10. Create two box plots using the Medical Insurance Column and the Sex Column. Please filter your Box Plots to account for the periods where the Smoking Status = Yes or the Smoking Status = No. From your box plots, what do you observe?
A75: Note: We've included an example for you so you'll know what to expect when you create your visualisation!
B76: Place your chart below here (Smoking = No ) | F76: Place your chart below here (Smoking = Yes )
A98: Great job so far! We're now ready to move onto the last part of our assignment - correlations!
A99: We know that correlation helps us understand the relationship between two variables and whether they share a linear relationship or not.
A100: Here we've noted age, BMI classification and regions - all might be related to our medical insurance charges.
A101: Q11. Using the CORREL() function, calculate the Correlation Value using the BMI and Medical Insurance Columns.
A102: Note: If you're stuck, please reference this link: https://support.microsoft.com/en-us/office/correl-function-995dcef7-0c0a-4bed-a3fb-239d7b68ca92
A103: What do you observe from the Correlation Value?
A104: Fill in the Correlation ( R ) value below
C105: BMI
...
